2019-07-02 23:54:15 ERROR (MainThread) [homeassistant.components.websocket_api.http.connection.139880462906200] Error handling message: Unknown error
Traceback (most recent call last):
  File "/usr/src/app/homeassistant/components/websocket_api/decorators.py", line 17, in _handle_async_response
    await func(hass, connection, msg)
  File "/usr/src/app/homeassistant/components/person/__init__.py", line 506, in ws_delete_person
    await manager.async_delete_person(msg['person_id'])
  File "/usr/src/app/homeassistant/components/person/__init__.py", line 230, in async_delete_person
    ent_reg.async_remove(entity.entity_id)
  File "/usr/src/app/homeassistant/helpers/entity_registry.py", line 165, in async_remove
    self.entities.pop(entity_id)
KeyError: 'person.camilo_avelar'
2019-07-02 23:54:33 ERROR (MainThread) [homeassistant.components.websocket_api.http.connection.139880462906200] Error handling message: Unknown error
Traceback (most recent call last):
  File "/usr/src/app/homeassistant/components/websocket_api/decorators.py", line 17, in _handle_async_response
    await func(hass, connection, msg)
  File "/usr/src/app/homeassistant/components/person/__init__.py", line 506, in ws_delete_person
    await manager.async_delete_person(msg['person_id'])
  File "/usr/src/app/homeassistant/components/person/__init__.py", line 221, in async_delete_person
    raise ValueError("Invalid person specified.")
ValueError: Invalid person specified.
2019-07-02 23:54:41 ERROR (MainThread) [homeassistant.components.websocket_api.http.connection.139880462906200] Error handling message: Unknown error
Traceback (most recent call last):
  File "/usr/src/app/homeassistant/components/websocket_api/decorators.py", line 17, in _handle_async_response
    await func(hass, connection, msg)
  File "/usr/src/app/homeassistant/components/person/__init__.py", line 506, in ws_delete_person
    await manager.async_delete_person(msg['person_id'])
  File "/usr/src/app/homeassistant/components/person/__init__.py", line 221, in async_delete_person
    raise ValueError("Invalid person specified.")
ValueError: Invalid person specified.
